Workbook
Name Goal_State: Results!#REF!
Name GoalState: #REF!
Name GoalState: Results!#REF!

Sheet Instructions
B1: Brand Assessment Tool
B2: Instructions
B3: Use this tool to analyze your organization's capabilities and ability to execute a successful branding program. | C3: Ranking Scale
B4: 1. In the "Weighting" tab, set the weighting for each category based on relevancy and current business needs. | C4: 1 - Strongly Disagree
B5: 2. In the "Self Assessment" tab, rank your organization on a scale of 1-5 on your compliance with each best practice. | C5: 2 - Disagree
B6: 3. Check the "Results" tab to identify your level of maturity in each category. | C6: 3 - Somewhat Agree
B7: 4. View the "Recommendations" tab for actionable advice on how to improve your capabilities. | C7: 4 - Agree
B8: 5. Learn more about The Sellani Group and their best-selling book What’s Your BQ? (Brand Quotient™) in the "About Author" tab. | C8: 5 - Strongly Agree

Sheet Weighting
B1: Brand Assessment Tool
B2: Weighting Scale
B3: Brand Strategy | C3: Brand Alignment | D3: Brand Communication | E3: Brand Execution | F3: Total
B4: 0.25 | C4: 0.25 | D4: 0.25 | E4: 0.25 | F4: =B4+C4+D4+E4 -> 1

Sheet Self Assessment
B1: Brand Assessment Tool
B2: Description of Best Practices | C2: Score | D2: Notes/Comments
B3: Brand Strategy
B4: My company's product or service has a strong point of difference from my competitors' product or service. | C4: 2
B5: I can summarize my brand essence in one word and one statement – so can most of my clients (i.e., Volvo = Safety, Nike = \“Just Do it\”). If so, give yourself a 5. | C5: 5
B6: The value of my product or service does not show a current threat of being outdated by new products or technologies. | C6: 3
B7: I regularly review my points of differentiation to ensure that they are not being imitated by my competitors. | C7: 4
B8: I have a clear understanding of my competitors' brand strength and weaknesses. | C8: 1
B9: I have a plan to help my brand survive if it is imitated by competitors. | C9: 4
B10: I have proprietary methods, technologies or other elements which other companies do not. | C10: 5
B11: My point of differentiation is difficult for my competitors to imitate. | C11: 3
B12: I am using my company's strengths to their fullest, in every level of the organization. | C12: 4
B13: I am building every level of the organization - operations, finance, marketing, administration, pricing - around the brand. | C13: 5
B15: Brand Alignment
B16: My brand is linked to my business's vision statement, culture, values and overall strategy. | C16: 2
B17: Employee reviews include reinforcement and rewards for supporting, communicating and championing the brand. (If you are a salesperson or a 1-man operation, give yourself a "5" for this. | C17: 1
B18: My employees can articulate or demonstrate how our offering differs from the competition. (Note: if you are a salesperson or a one-man operation, rank this on how it applies to you. | C18: 3
B19: My sales staff communicates our differentiation to the client in a consistent manner to show competitive advantages (Note: If you are a salesperson or a one-man operation, rank this on how it applies to you.) | C19: 5
B20: Customers buy from me not just for the product but for a unique experience they get when using the product. | C20: 1
B21: I regularly survey my customers to ensure that I am providing a product or service that is valuable and relevant. | C21: 4
B22: I incorporate feedback from prospects, customers, vendors and the media to improve my offering. | C22: 2
B23: My management team buys into the brand offering and actively incorporates it into their daily operations. (Note: If you are a salesperson or a one-man organization, rank this on how it applies to you.) | C23: 3
B24: My management team makes decisions based on whether or not it will support or negate the brand. (Note: if you are a sales person or a on-man organization, rank this on how it applies to you.) | C24: 1
B25: I am not the low price leader in my category. | C25: 4
B27: Brand Communication
B28: My marketing materials clearly communicate my companies brand and points of competitive differentiation. | C28: 1
B29: My company is free of scandal and negative publicity. | C29: 2
B30: All marketing materials - print, electronic, web - have continuity in their colors, images, and messaging. | C30: 1
B31: I leverage my brand with publicity and regular contacts with the media. | C31: 1
B32: I have and enforce a graphic branding standards manual that explains how each element of my brand should be dealt with in the operation of the business (i.e., colors of logo, layout of graphics on stationery, font sizes to be used) to ensure that all graphic elements of my brand are consistent. | C32: 4
B33: The quality of my marketing materials are equal to or greater than the quality of my services. | C33: 1
B34: My sales team does not create or customize their materials in a way that alters the brand image or message. (Note: If you are a salesperson or a one-man operation, rate this on how it applies to you.) | C34: 2
B35: My management team reinforces brand messages in their staff meetings and interactions. (Note: If you are a salesperson or one-man operation, give yourself a "5") | C35: 2
B36: My messages, ads, graphics and colors have remained consistent over time, unless there was a specific change strategy in place. | C36: 1
B37: My sales team uses an emotional component to encourage and reinforce use of the brand. (Note: If you are a sales person or one-man operation rate this on whether or not you employ this tactic.) | C37: 1
B39: Brand Execution
B40: My company's phone is answered by a pleasant, knowledgeable individual who can quickly and amiably meet the caller's needs. | C40: 4
B41: I understand that my brand exists only in the minds of my customers and prospects. | C41: 5
B42: My company resolves customer service issues promptly and efficiently to the client's satisfaction. | C42: 3
B43: I regularly receive superior customer satisfaction ratings when I survey my customers. | C43: 1
...

Sheet Results
B1: Brand Assessment Tool
B2: DO NOT ENTER VALUES INTO THIS SPREADSHEET
B3: Branding Dimensions | C3: Level | D3: Weight | E3: Report Card
B4: ='Self Assessment'!B3:D3 -> Brand Strategy | C4: =AVERAGE('Self Assessment'!C4:C13) -> 3.6 | D4: =Weighting!B$4 -> 0.25
B5: ='Self Assessment'!B15:D15 -> Brand Alignment | C5: =AVERAGE('Self Assessment'!C16:C25) -> 2.6 | D5: =Weighting!C$4 -> 0.25
B6: ='Self Assessment'!B27:D27 -> Brand Communication | C6: =AVERAGE('Self Assessment'!C28:C37) -> 1.6 | D6: =Weighting!D$4 -> 0.25
B7: ='Self Assessment'!B39:D39 -> Brand Execution | C7: =AVERAGE('Self Assessment'!C40:C49) -> 4.2 | D7: =Weighting!E$4 -> 0.25
B8: Overall Weighted Average (out of 5) | C8: =(C4*Weighting!B4)+(C5*Weighting!C4)+(C6*Weighting!D4)+(C7*Weighting!E4) -> 3 | D8: =SUM(D4:D7) -> 1

Sheet Recommendations
B1: Brand Assessment Tool
B2: DO NOT ENTER VALUES INTO THIS SPREADSHEET.
B3: Branding Dimensions | C3: Scores | D3: Recommendations | E3: Resource Links
B4: ='Self Assessment'!B3:D3 -> Brand Strategy
B5: My company's product or service has a strong point of difference | C5: ='Self Assessment'!C4 -> 2 | D5: Determine what you do that you competitors do not and reinforce that message regularly.
B6: My clients & I can summarize my brand in one word & one statement | C6: ='Self Assessment'!C5 -> 5 | D6: When you have completely brand clarity, your messaging will too.
B7: The value of my product/service does not show a threat of being outdated | C7: ='Self Assessment'!C6 -> 3 | D7: Look at industry trends and stay ahead of the curve or risk obsolescence.
B8: I regularly review my points of differentiation | C8: ='Self Assessment'!C7 -> 4 | D8: Competitors will imitate you - have a plan of action to keep your difference clear in the mind of the consumer.
B9: I have a clear understanding of competitors' brand strength & weaknesses | C9: ='Self Assessment'!C8 -> 1 | D9: Analyze you top five competitors and their perception in the marketplace.
B10: I have a plan to help my brand survive if it is imitated by competitors | C10: ='Self Assessment'!C9 -> 4 | D10: Think two steps ahead and plan how you will inform consumers why your offering is superior to "copycats".
B11: I have proprietary methods, technologies or other elements | C11: ='Self Assessment'!C10 -> 5 | D11: Trademarks, processes, and proprietary techniques can make your offering difficult for others to imitate.
B12: My point of differentiation is difficult for my competitors to imitate | C12: ='Self Assessment'!C11 -> 3 | D12: Products & services can be imitated - brands cannot. Sell the value of the brand, not the product.
B13: I use my company's strengths to the fullest, in every level of the org. | C13: ='Self Assessment'!C12 -> 4 | D13: Make sure your core competencies are being fully utilized throughout the company.
B14: I am building every level of the organization around the brand | C14: ='Self Assessment'!C13 -> 5 | D14: Everyone is a brand ambassador. Ensure that each department reinforces the brand message.
A15: Look at industry trends and stay ahead of the curve or risk obsolescence.
B16: ='Self Assessment'!B15:D15 -> Brand Alignment
B17: My brand is linked to my vision statement, culture, values & strategy | C17: ='Self Assessment'!C16 -> 2 | D17: Branding is a function of the corporation, not just the marketing department. Tie it into overall corporate objectives.
B18: Employee reviews include rewards for championing the brand | C18: ='Self Assessment'!C17 -> 1 | D18: Add a line item to your employee performance process to enforce good branding behavior throughout the organization.
B19: Employees can articulate how our offering differs from the competition | C19: ='Self Assessment'!C18 -> 3 | D19: Every employee should know what makes your company different in the market. Ask them and see if they do.
B20: Sales staff communicates our differentiation in a consistent manner | C20: ='Self Assessment'!C19 -> 5 | D20: Branding is often diluted when every member of the sales team gives different messages. Ensure consistency in the sales, presentation and RFP process.
B21: Customers buy for a unique experience they get when using the product | C21: ='Self Assessment'!C20 -> 1 | D21: Customers don't buy products, they buy brands, because branding transcends the transaction itself.
B22: I regularly survey my customers | C22: ='Self Assessment'!C21 -> 4 | D22: Customers who are surveyed are more likely to stay and buy more products, even if they are unhappy with you at the time of the survey.
B23: I incorporate feedback from prospects, customers, vendors and the media | C23: ='Self Assessment'!C22 -> 2 | D23: Let your stakeholders know that you value their opinions and when you've made changes as a result.
B24: My management team buys into the brand offering | C24: ='Self Assessment'!C23 -> 3 | D24: If everyone on the team does not support the brand, you will dilute your own branding efforts.
B25: Management makes decisions based on support or negate of the brand | C25: ='Self Assessment'!C24 -> 1 | D25: Branding should be kept in mind during all decision making processes - not just decisions involving marketing.
B26: I am not the low price leader in my category | C26: ='Self Assessment'!C25 -> 4 | D26: If people are paying more for your services, chances are they see a point of differentiation. Don't just ask if they're buying, ask why they're buying from YOU instead of your competition.
A27: Look at industry trends and stay ahead of the curve or risk obsolescence.
B28: ='Self Assessment'!B27:D27 -> Brand Communication
B29: My marketing materials clearly communicate my companies brand | C29: ='Self Assessment'!C28 -> 1 | D29: Every marketing piece should communicate your point of differentiation and brand identity.
B30: My company is free of scandal and negative publicity | C30: ='Self Assessment'!C29 -> 2 | D30: Brands take years to build and moments to destroy. Have a PR crisis plan to deal with the media when the unexpected happens.
B31: All marketing materials have continuity | C31: ='Self Assessment'!C30 -> 1 | D31: Put all of your materials on a table - they should all look like they came from the same company, have consistent messaging, imaging and quality.
B32: I leverage my brand with publicity and regular contacts with the media | C32: ='Self Assessment'!C31 -> 1 | D32: Keep on good terms with the media. Become a resource to them for issues in your industry - even if the story they're covering is not on you per se.
B33: I have and enforce a graphic branding standards manual | C33: ='Self Assessment'!C32 -> 4 | D33: A branding standards manual is essential to ensure brand consistency companywide. Get help from a brand strategist or designer to create one.
B34: Quality of marketing materials are equal or greater than quality of services | C34: ='Self Assessment'!C33 -> 1 | D34: Is your service elegant? Earthy? Sophisticated? Humorous? Make sure your materials reflect the personality and quality of the brand.
B35: Sales team does not create/customize materials in a way that alters brand | C35: ='Self Assessment'!C34 -> 2 | D35: Ensure that all sales materials are consistent - sales people will create their own, often diluting the brand message.
B36: Management team reinforces brand in staff meetings & interactions | C36: ='Self Assessment'!C35 -> 2 | D36: Every manager should regularly refer to how their department is supporting the overall brand experience in the company.
B37: My messages, ads, graphics and colors have remained consistent | C37: ='Self Assessment'!C36 -> 1 | D37: Don't change your imagery, tagline or messaging on a whim. Consumers want consistency. Define your brand and stick with it.
B38: Sales team uses an emotional component to encourage and reinforce brand | C38: ='Self Assessment'!C37 -> 1 | D38: People usually buy because of an emotional component. Find the emotion in the transaction that goes beyond the product or service.
A39: Look at industry trends and stay ahead of the curve or risk obsolescence.
B40: ='Self Assessment'!B39:D39 -> Brand Execution
...

Sheet About Author
B1: Brand Assessment Tool
B2: Demand Metric had the pleasure of collaborating with expert branding consultant Sandra Sellani of The Sellani Group in the creation of this assessment. Following is a brief biography of Sandra Sellani:
B4: Author, consultant, speaker and trainer Sandra Sellani is Principal of The Sellani Group Brand Strategists, a full-service Newport Beach, California based consultancy. The Sellani Group helps companies build, leverage and maximize the value of their brands by focusing on their strongest point of competitive differentiation.
B5: The group enables companies to get their marketing and branding right the first time with one simple rule: Strategy Before Creative. To this end, Sandra develops a brand plan that is fully integrated with the overall corporate plan to ensure that company branding is leveraged throughout the organization - in creative elements such as marketing materials and at every client touch point throughout the organization. Her proprietary programs include:
B6: The One-Day Brand Strategy Session™ to help companies define and optimize their brand,
B7: The Brand Quotient Test™, a corporate brand diagnostic and metric tool,
B8: The Executive Brand Quotient Assessment™, a comprehensive tool that combines individual behavioral traits with branding methods for executives in transition who want to develop or change their own personal brands.
B9: The 60-Minute Strategic Plan® a method that enables company employees at every level to create well-organized strategic plans for projects within their respective departments.
B10: Upon creation of a strategy, the firm provides all creative elements of a full service design and marketing firm including: logos and corporate identity packages, websites, brochures, and other collateral material, public relations and social media campaigns.
B11: Her award-winning book, What’s Your BQ? (Brand Quotient™) launched to #12 in Marketing , # 7 in Branding and #2 in Product Management on Amazon.com. The book was named, Winner, Non-Fiction, DIY Book Festival and received an Honorable Mention, Non-Fiction, in the London Book Festival.
B12: Sandra has been interviewed and featured for her brand expertise in media including: Sales & Service Excellence Magazine, Yahoo! Finance, The National Association of Realtors Online Magazine, SmartMoney.com, Investor’s Business Daily and Moodley Brand Identity, one of Austria’s leading brand agencies. Sandra speaks to organizations, CEOs, senior level executives and entrepreneurs nationwide on how to build powerful, inimitable brands.
B13: Sandra is an active member of the Orange County Association of Strategic Planning and NAWBO (National Association of Women Business Owners). She is an executive MBA from Pepperdine University, Malibu, California. For more information, visit www.sandrasellani.com, www.whatsyourbq.com or follow Sandra on Twitter at ssbrand.
